# Вложенные исключения
Если бросить первое исключение, не успеть обработать его и бросить второе, то информация о первом потеряется. Можно попробовать засунуть информацию о первом исключение во второе - это называется вложенные исключения.

```cpp
class MyException : public exception
{
public:
	MyException(string message) : m_message{ move(message) } {}
	const char* what() const noexcept override { return m_message.c_str(); }
private:
	string m_message;
};

void doSomething()
{
	try {
		throw runtime_error{ "Throwing a runtime_error exception" };
	}
	catch (const runtime_error& e) {
		cout << format("{} caught a runtime_error", __func__) << endl;
		cout << format("{} throwing MyException", __func__) << endl;
		throw_with_nested(
			MyException{ "MyException with nested runtime_error" });
	}
}
int main(int argc, char* argv[])
{
	try
	{
		doSomething();
	}
	catch (const MyException& e)
	{
		cout << format("{} caught MyException: {}", __func__, e.what()) << endl;
		const auto* nested{ dynamic_cast<const nested_exception*>(&e) };
		try {
			rethrow_if_nested(e);
		}
		catch (const runtime_error& e) {
			// Handle nested exception.
			cout << format("Nested exception: {}", e.what()) << endl;
		}
	}
	
}
/*
	doSomething caught a runtime_error
	doSomething throwing MyException
	main caught MyException: MyException with nested runtime_error
	Nested exception: Throwing a runtime_error exception
*/
```