# Исключения и множественное наследование
```cpp
struct my_exc1 : std::exception {  
    char const *what() const noexcept override { return "exc1"; }  
};  
  
struct my_exc2 : std::exception {  
    char const *what() const noexcept override { return "exc2"; }  
};  
  
struct your_exc3 : my_exc1, my_exc2 {};  
  
int main() {  
    try {  
        throw your_exc3();  
    } catch (std::exception const &e) {  
        std::cout << e.what() << std::endl;  
    } catch (...) {  
        std::cerr << "whoops!\n";  
    }  
    //whoops!  
}
```

Поскольку your_exc3() ссылается на 2 варианта базового класса, компилятор не может решить на какой именно и проваливается на уровень ниже. Решение - виртуальное наследование

```cpp
struct my_exc1 : virtual std::exception {  
    char const *what() const noexcept override { return "exc1"; }  
};  
  
struct my_exc2 : virtual std::exception {  
    char const *what() const noexcept override { return "exc2"; }  
};  
  
struct your_exc3 : my_exc1, my_exc2 {  
    char const *what() const noexcept override { return "exc3"; }  
};  
  
int main() {  
    try {  
        throw your_exc3();  
    } catch (std::exception const &e) {  
        std::cout << e.what() << std::endl;  
    } catch (...) {  
        std::cerr << "whoops!\n";  
    }  
    //exc3!  
}
```

Не стоит использовать Обобщенный тип в catch(...) поскольку мы т.о. можем поймать исключение, которое не должны были, т.е. оно должно дальше лететь по стеку и где-то корректно обработаться, а не у нас. Так что его лучше никогда не писать. Но есть конечно специальные случаи, например освобождение памяти