# Механизм обработки исключений
```cpp
void A()
{	
	ifstream fstr("output.txt");
	if (!fstr)
		throw exception{ "file not found" };
	//...
}



int main(int argc, char* argv[])
{
	try
	{
		A();
	}
	catch (const exception& e)
	{
		cout << e.what();
	}
}
```

```plantuml
start 
:Вызваем функцию A(), 
пытаемся открыть файл для ввода; 
if (Пытаемся открыть файл) then(Файла нет)
	:Выбрасываем исключения: "Файл не найден";
	:Вызывающая сторона ловит его и обрабатывает 
	с помощью блока try/catch,выводя информацию 
	об исключении; 
else (Файл есть)
	:Работаем с файлом;
	:Закрываем его и передаем управление в main;
stop 
endif 
stop
```

1. Блок try предназначен для того, что после выброса исключения ваша программа не упала
2. Блок catch предназначен для обработки исключений, если исключений не было выброшено, блок try не выполняется


```cpp
struct UnwShow {  
    int n_;  
    long t = 0xDEADBEEF;  
    UnwShow(int n) : n_(n) { std::cout << "ctor: " << n_ << "\n"; }  
    ~UnwShow() { std::cerr << "dtor: " << n_ << "\n"; }  
};  
  
void foo(int n) {  
    UnwShow s{n};  
  
    // odr-use to materialize  
    std::cout << "Addr of " << n << ": " << &s << std::endl;  
    if (n == 0) {  
        std::cout << "throw\n";  
        throw 1;  
    }  
    foo(n - 1);  
}  
  
int main() {  
    try {  
        foo(5);  
    } catch (int n) {  
        std::cout << "catch\n";  
    }  
}  
/*  
ctor: 5  
Addr of 5: 0x7ffd7401af30  
ctor: 4  
Addr of 4: 0x7ffd7401aee0  
ctor: 3  
Addr of 3: 0x7ffd7401ae90  
ctor: 2  
Addr of 2: 0x7ffd7401ae40  
ctor: 1  
Addr of 1: 0x7ffd7401adf0  
ctor: 0  
Addr of 0: 0x7ffd7401ada0  
throw  
dtor: 0  
dtor: 1  
dtor: 2  
dtor: 3  
dtor: 4  
dtor: 5  
catch  
*/
```

`throw <expression>` означает - создать объект исключения и начать раскрутку стека - при раскрутке стека мы как обычно выходим из функции, локальные переменные уничтожаются. Раскрутка будет продолжаться до тех пор, пока вы его не поймаете, то есть до первого блока try/catch, который сможет его обработать, т.е. если типы исключения в catch не совпадают, либо они не родственные, то раскрутка продолжится. Кроме того, никакие типы кроме родственных,  не преобразуются, т.е. int не будет конвертироваться в double, а Derived может урезать в Base

```cpp
void g()  
{  
    throw 1;  
}  
  
void foo(int x)  
{  
    try{  
        g();  
    }  
    catch (double i) {  
        cout << "double";  
    }  
}  
  
int main() {  
    try {  
        foo(5);  
    } catch (int n) {  
        std::cout << "int";  
    }  
}
//int  
```

Исключение дорого если его бросать.