# Обработка исключений
Ошибки - которые не являются исключительными ситуациями:
1. Рантайм ошибки, после которых состояние не восстановимо(например segmentation fault)
2. Ошибки контракта функции(assertion faiure из-за неверных аргументов, невыполненные предусловия вызова)

Исключительные ситуации:
1. Состояние программы должно быть восстановимо (например: исчерпание памяти или отсутствие файла на диске)
2. Исключительная ситуация не может быть обработана на том уровне, на котором возникла (программа сортировки не обязана знать что делать при нехватке памяти на временный буфер)

Исключения нужны только для действительно исключительных, неожиданных ситуаций(выход за пределы массива).

Исключение - это способ уведомить вызывающую часть кода(функцию, а функция в свою очередь уведомляет другую вышестоящую функцию, пока исключение не поймают, не обработают) о том, что произошла исключительная ситуация.

Если во время выброса исключения, возникает еще одно исключение - это `termiante()`, с помощью `uncaught_exceptions()` можно проверять есть ли непойманное исключение

```cpp
if(std::uncaught_exceptions())
	...
else
	throw..
```

Чем хороши исключения? В отличии от вериницы if'ов, с помощью исключений мы можем писать код по порядку, который компилятор хорошо оптимизирует
* [[Механизм обработки исключений]]
* [[Типы исключений]]
* [[Ключевое слово noexcept]]
* [[Вложенные исключения]]
* [[Повторный выброс исключений]]
* [[Раскрутка стека при выбросе исключения]]
* [[Обработка исключительных ситуаций в списке инициализаций]]
* [[Безопасность в исключительных ситуаций]]
#do/review 
```cpp
struct UnwShow {  
    int n_;  
    long t = 0xDEADBEEF;  
    UnwShow(int n) : n_(n) { std::cout << "ctor: " << n_ << "\n"; }  
    ~UnwShow() { std::cerr << "dtor: " << n_ << "\n"; }  
};  
  
void foo(int n) {  
    UnwShow s{n};  
  
    // odr-use to materialize  
    std::cout << "Addr of " << n << ": " << &s << std::endl;  
    if (n == 0) {  
        std::cout << "throw\n";  
        throw 1;  
    }  
    foo(n - 1);  
}  
  
int main() {  
    try {  
        foo(5);  
    } catch (int n) {  
        std::cout << "catch\n";  
    }  
}  
/*  
ctor: 5  
Addr of 5: 0x7ffd7401af30  
ctor: 4  
Addr of 4: 0x7ffd7401aee0  
ctor: 3  
Addr of 3: 0x7ffd7401ae90  
ctor: 2  
Addr of 2: 0x7ffd7401ae40  
ctor: 1  
Addr of 1: 0x7ffd7401adf0  
ctor: 0  
Addr of 0: 0x7ffd7401ada0  
throw  
dtor: 0  
dtor: 1  
dtor: 2  
dtor: 3  
dtor: 4  
dtor: 5  
catch  
*/
```

`throw <expression>` означает - создать объект исключения и начать раскрутку стека - при раскрутке стека мы как обычно выходим из функции, локальные переменные уничтожаются. Раскрутка будет продолжаться до тех пор, пока вы его не поймаете, то есть до первого блока try/catch, который сможет его обработать, т.е. если типы исключения в catch не совпадают, либо они не родственные, то раскрутка продолжится. Кроме того, никакие типы кроме родственных,  не преобразуются, т.е. int не будет конвертироваться в double, а Derived может урезать в Base

```cpp
void g()  
{  
    throw 1;  
}  
  
void foo(int x)  
{  
    try{  
        g();  
    }  
    catch (double i) {  
        cout << "double";  
    }  
}  
  
int main() {  
    try {  
        foo(5);  
    } catch (int n) {  
        std::cout << "int";  
    }  
}
//int  
```

Исключение дорого если его бросать.

# Исключения и множественное наследование
```cpp
struct my_exc1 : std::exception {  
    char const *what() const noexcept override { return "exc1"; }  
};  
  
struct my_exc2 : std::exception {  
    char const *what() const noexcept override { return "exc2"; }  
};  
  
struct your_exc3 : my_exc1, my_exc2 {};  
  
int main() {  
    try {  
        throw your_exc3();  
    } catch (std::exception const &e) {  
        std::cout << e.what() << std::endl;  
    } catch (...) {  
        std::cerr << "whoops!\n";  
    }  
    //whoops!  
}
```

Поскольку your_exc3() ссылается на 2 варианта базового класса, компилятор не может решить на какой именно и проваливается на уровень ниже. Решение - виртуальное наследование

```cpp
struct my_exc1 : virtual std::exception {  
    char const *what() const noexcept override { return "exc1"; }  
};  
  
struct my_exc2 : virtual std::exception {  
    char const *what() const noexcept override { return "exc2"; }  
};  
  
struct your_exc3 : my_exc1, my_exc2 {  
    char const *what() const noexcept override { return "exc3"; }  
};  
  
int main() {  
    try {  
        throw your_exc3();  
    } catch (std::exception const &e) {  
        std::cout << e.what() << std::endl;  
    } catch (...) {  
        std::cerr << "whoops!\n";  
    }  
    //exc3!  
}
```

Не стоит использовать Обобщенный тип в catch(...) поскольку мы т.о. можем поймать исключение, которое не должны были, т.е. оно должно дальше лететь по стеку и где-то корректно обработаться, а не у нас. Так что его лучше никогда не писать. Но есть конечно специальные случаи, например освобождение памяти

# Недостатки
code path disruption - неоднозначность выполнения кода, если исключение выйдет

#do/start 
1. https://monkeywritescode.blogspot.com/p/c-exceptions-under-hood.html
2. https://venus.cs.qc.edu/~waxman/780/exceptions/exceptionarticle.pdf