# Повторный выброс исключений
```cpp
void g() { throw invalid_argument{ "Some exception" }; }
void f()
{
	try {
		g();
	}
	catch (const invalid_argument& e) {
		cout << "caught in f: " << e.what() << endl;
		throw; // rethrow
	}
}
int main()
{
	try {
		f();
	}
	catch (const invalid_argument& e) {
		cout << "caught in main: " << e.what() << endl;
	}
}
/*
	caught in f: Some exception
	caught in main: Some exception
*/
```

Писать `throw e` не стоит, т.к. по неосторожности можно урезать объект:

```cpp
void g() { throw invalid_argument{ "Some exception" }; }
void f()
{
	try {
		g();
	}
	catch (const exception& e) {
		cout << "caught in f: " << e.what() << endl;
		throw; // rethrow
	}
}
int main()
{
	try {
		f();
	}
	catch (const invalid_argument& e) {
		cout << "invalid_argument caught in main: " << e.what() << endl;
	}
	catch (const exception& e) {
		cout << "exception caught in main: " << e.what() << endl;
	}
}
/*
	caught in f: Some exception
	exception caught in main: Some exception
*/
```

```plantuml
class exceptions
class invalid_argument
exceptions <|-- invalid_argument
```